Workbook
Name 제품목록: 'RD.참조DATA'!$A:$F

Sheet I.납품일정
B1: I. 인터로조 PO / 납품 스케줄 | E1: Ver. 2605271900
B2: 기간 : 5월1일~5월30일
B4: 발주일자 | C4: 규 격 | D4: dl | E4: 작지No. | F4: PO량 | G4: 요청 납기 | H4: 조정 납기 | I4: 확정 납기 | J4: 납기확정사항 (생산기획팀) | K4: 완료구분 | L4: 세부사항 | M4: L관재고 | N4: PO잔량 | O4: 합계 | P4: 46146 | Q4: 46149 | R4: 46150 | S4: 46153 | T4: 46154 | U4: 46155 | V4: 46157 | W4: 46160 | X4: 46161 | Y4: 46162 | Z4: 46163 | AA4: 46164 | AB4: 46168 | AC4: 46169 | AD4: 46170 | AE4: 46171 | AJ4: 비 고
B5: 46142 | C5: BS0073 | D5: =IFERROR(VLOOKUP(C5,제품목록,3,FALSE),"") -> 알루미늄리드지 (일본 PIA 1day 55%)_유광 코팅 | F5: 838000 | G5: 46141 | K5: 완료 | N5: =F5-O5 -> 22000 | O5: =SUM(P5:AI5) -> 816000 | P5: 816000 | W5: 0 | Z5: 0 | AJ5: =SUM(X5:AI5) -> 0
B6: 46128 | C6: BS0073 | D6: =IFERROR(VLOOKUP(C6,제품목록,3,FALSE),"") -> 알루미늄리드지 (일본 PIA 1day 55%)_유광 코팅 | F6: 5000000 | G6: 5/11 | K6: 완료 | N6: =F6-O6 -> -147000 | O6: =SUM(P6:AI6) -> 5147000 | P6: 400000 | Q6: 385000 | R6: 756000 | S6: 917000 | T6: 749000 | U6: 717000 | W6: 700000 | X6: 523000
B7: 46164 | C7: BS0073 | D7: =IFERROR(VLOOKUP(C7,제품목록,3,FALSE),"") -> 알루미늄리드지 (일본 PIA 1day 55%)_유광 코팅 | F7: 2000000 | G7: 5/29 | K7: 완료 | N7: =F7-O7 -> 28000 | O7: =SUM(P7:AI7) -> 1972000 | Z7: 492000 | AA7: 953000 | AB7: 527000
B8: 46105 | C8: BS0176 | D8: =IFERROR(VLOOKUP(C8,제품목록,3,FALSE),"") -> 알루미늄리드지 (일본 sincere ITFA 1D 38% UV)_유광 코팅 | F8: 200000 | G8: 46113 | H8: 46114 | K8: 완료 | M8: =IFERROR(_xlfn.XLOOKUP(C8,[1]III.재고현황!O:O,[1]III.재고현황!R:R),) -> 240000 | N8: =F8-O8 -> -40000 | O8: =SUM(P8:AI8) -> 240000 | P8: 240000 | AJ8: =SUM(X8:AI8) -> 0
B9: 46105 | C9: BS0057 | D9: =IFERROR(VLOOKUP(C9,제품목록,3,FALSE),"") -> 알루미늄리드지 (Iris-알리샤브라운)_무광 코팅 | F9: 300000 | G9: 46118 | H9: 46121 | K9: 완료 | M9: =IFERROR(_xlfn.XLOOKUP(C9,[1]III.재고현황!O:O,[1]III.재고현황!R:R),) -> 539000 | N9: =F9-O9 -> -45000 | O9: =SUM(P9:AI9) -> 345000 | Q9: 345000 | AJ9: =SUM(X9:AI9) -> 0
B10: 46105 | C10: BS0265 | D10: =IFERROR(VLOOKUP(C10,제품목록,3,FALSE),"") -> 알루미늄리드지 (태국 MG Medical Group_HYA 중사각 인쇄 리드지)_무광코팅 | F10: 150000 | G10: 46118 | H10: 46121 | K10: 완료 | M10: =IFERROR(_xlfn.XLOOKUP(C10,[1]III.재고현황!O:O,[1]III.재고현황!R:R),) -> 201600 | N10: =F10-O10 -> 150000 | O10: =SUM(P10:AI10) -> 0 | AJ10: =SUM(X10:AI10) -> 0
B11: 46105 | C11: BS0270 | D11: =IFERROR(VLOOKUP(C11,제품목록,3,FALSE),"") -> 알루미늄리드지 (태국 MG M_GLAM No.1 Hazel 중사각 인쇄 리드지) | F11: 250000 | G11: 46118 | H11: 46121 | K11: 완료 | M11: =IFERROR(_xlfn.XLOOKUP(C11,[1]III.재고현황!O:O,[1]III.재고현황!R:R),) -> 163200 | N11: =F11-O11 -> 250000 | O11: =SUM(P11:AI11) -> 0 | AJ11: =SUM(X11:AI11) -> 0
B12: 46105 | C12: BS0149 | D12: =IFERROR(VLOOKUP(C12,제품목록,3,FALSE),"") -> 알루미늄리드지 (Clalen O2O2 Color 1Day)_무광 코팅 | F12: 1000000 | G12: 46118 | H12: 46118 | K12: 완료 | M12: =IFERROR(_xlfn.XLOOKUP(C12,[1]III.재고현황!O:O,[1]III.재고현황!R:R),) -> 2473000 | N12: =F12-O12 -> -44000 | O12: =SUM(P12:AI12) -> 1044000 | Q12: 1044000 | AJ12: =SUM(X12:AI12) -> 0
B13: 46105 | C13: BS0341 | D13: =IFERROR(VLOOKUP(C13,제품목록,3,FALSE),"") -> 알루미늄리드지 (PIA_1M 38% Melady 리드지) | F13: 200000 | G13: 46120 | H13: 46118 | K13: 완료 | M13: =IFERROR(_xlfn.XLOOKUP(C13,[1]III.재고현황!O:O,[1]III.재고현황!R:R),) -> 192000 | N13: =F13-O13 -> -41000 | O13: =SUM(P13:AI13) -> 241000 | R13: 241000 | AJ13: =SUM(X13:AI13) -> 0
B14: 46105 | C14: BS0318 | D14: =IFERROR(VLOOKUP(C14,제품목록,3,FALSE),"") -> 알루미늄리드지 (PIA_1M 38% feliamo 리드지) | F14: 200000 | G14: 46120 | H14: 46118 | K14: 완료 | M14: =IFERROR(_xlfn.XLOOKUP(C14,[1]III.재고현황!O:O,[1]III.재고현황!R:R),) -> 240000 | N14: =F14-O14 -> -40000 | O14: =SUM(P14:AI14) -> 240000 | S14: 240000 | AJ14: =SUM(X14:AI14) -> 0
B15: 46105 | C15: BS0317 | D15: =IFERROR(VLOOKUP(C15,제품목록,3,FALSE),"") -> 알루미늄리드지 (PIA_1M 38% MOLAK 리드지) | F15: 200000 | G15: 46120 | H15: 46119 | K15: 완료 | M15: =IFERROR(_xlfn.XLOOKUP(C15,[1]III.재고현황!O:O,[1]III.재고현황!R:R),) -> 202000 | N15: =F15-O15 -> -50000 | O15: =SUM(P15:AI15) -> 250000 | S15: 250000 | AJ15: =SUM(X15:AI15) -> 0
B16: 46105 | C16: BS0337 | D16: =IFERROR(VLOOKUP(C16,제품목록,3,FALSE),"") -> 알루미늄리드지 (PIA_1M 38% TOPARDS 리드지) | F16: 200000 | G16: 46120 | H16: 46120 | K16: 완료 | M16: =IFERROR(_xlfn.XLOOKUP(C16,[1]III.재고현황!O:O,[1]III.재고현황!R:R),) -> 192000 | N16: =F16-O16 -> -40000 | O16: =SUM(P16:AI16) -> 240000 | S16: 240000 | AJ16: =SUM(X16:AI16) -> 0
B17: 46111 | C17: BS0333 | D17: =IFERROR(VLOOKUP(C17,제품목록,3,FALSE),"") -> 알루미늄리드지 (Monthly_무지) (80mm) | F17: 1000000 | G17: 46128 | H17: 46122 | K17: 완료 | M17: =IFERROR(_xlfn.XLOOKUP(C17,[1]III.재고현황!O:O,[1]III.재고현황!R:R),) -> 846609 | N17: =F17-O17 -> 1000000 | O17: =SUM(P17:AI17) -> 0 | AJ17: =SUM(X17:AI17) -> 0
B18: 46111 | C18: BS0057 | D18: =IFERROR(VLOOKUP(C18,제품목록,3,FALSE),"") -> 알루미늄리드지 (Iris-알리샤브라운)_무광 코팅 | F18: 200000 | G18: 46118 | H18: 46120 | K18: 완료 | M18: =IFERROR(_xlfn.XLOOKUP(C18,[1]III.재고현황!O:O,[1]III.재고현황!R:R),) -> 539000 | N18: =F18-O18 -> -42000 | O18: =SUM(P18:AI18) -> 242000 | Q18: 242000 | AJ18: =SUM(X18:AI18) -> 0
B19: 46111 | C19: BS0115 | D19: =IFERROR(VLOOKUP(C19,제품목록,3,FALSE),"") -> 알루미늄리드지 (무지-백색_PET12/AL30/CPP100_White 리버스인쇄) | F19: 2000000 | G19: 46120 | K19: 완료 | M19: =IFERROR(_xlfn.XLOOKUP(C19,[1]III.재고현황!O:O,[1]III.재고현황!R:R),) -> 835000 | N19: =F19-O19 -> 1300000 | O19: =SUM(P19:AI19) -> 700000 | Y19: 700000 | AF19: 0 | AJ19: =SUM(X19:AI19) -> 700000
B20: 46111 | C20: BS0053 | D20: =IFERROR(VLOOKUP(C20,제품목록,3,FALSE),"") -> 알루미늄리드지 (국내/중국 1-Day Soft)_무광 코팅 | F20: 1500000 | G20: 46120 | H20: 46122 | K20: 완료 | M20: =IFERROR(_xlfn.XLOOKUP(C20,[1]III.재고현황!O:O,[1]III.재고현황!R:R),) -> 3829000 | N20: =F20-O20 -> -47000 | O20: =SUM(P20:AI20) -> 1547000 | T20: 1547000 | AJ20: =SUM(X20:AI20) -> 0
B21: 46111 | C21: BS0343 | D21: =IFERROR(VLOOKUP(C21,제품목록,3,FALSE),"") -> 알루미늄리드지 (렌즈미 CleanFit O2 clear 1Day (30개입)) | F21: 1000000 | G21: 46122 | H21: 4/23 | K21: 완료 | M21: =IFERROR(_xlfn.XLOOKUP(C21,[1]III.재고현황!O:O,[1]III.재고현황!R:R),) -> 0 | N21: =F21-O21 -> 42000 | O21: =SUM(P21:AI21) -> 958000 | AD21: 481000 | AE21: 477000 | AJ21: =SUM(X21:AI21) -> 958000
B22: 46111 | C22: BS0149 | D22: =IFERROR(VLOOKUP(C22,제품목록,3,FALSE),"") -> 알루미늄리드지 (Clalen O2O2 Color 1Day)_무광 코팅 | F22: 1000000 | G22: 46125 | K22: 완료 | M22: =IFERROR(_xlfn.XLOOKUP(C22,[1]III.재고현황!O:O,[1]III.재고현황!R:R),) -> 2473000 | N22: =F22-O22 -> 1000000 | O22: =SUM(P22:AI22) -> 0 | V22: 0 | AJ22: =SUM(X22:AI22) -> 0
B23: 46111 | C23: BS0086 | D23: =IFERROR(VLOOKUP(C23,제품목록,3,FALSE),"") -> 알루미늄리드지 (Iris_수지브라운)_무광 코팅 | F23: 1000000 | G23: 46126 | H23: 4/27 | K23: 완료 | M23: =IFERROR(_xlfn.XLOOKUP(C23,[1]III.재고현황!O:O,[1]III.재고현황!R:R),) -> 0 | N23: =F23-O23 -> -15000 | O23: =SUM(P23:AI23) -> 1015000 | W23: 0 | AF23: 487000 | AG23: 528000 | AJ23: =SUM(X23:AI23) -> 1015000
B24: 46114 | C24: BS0316 | D24: =IFERROR(VLOOKUP(C24,제품목록,3,FALSE),"") -> 알루미늄리드지 (PIA_1M 38% LILMOON 리드지) | F24: 200000 | G24: 46120 | H24: 46119 | K24: 완료 | M24: =IFERROR(_xlfn.XLOOKUP(C24,[1]III.재고현황!O:O,[1]III.재고현황!R:R),) -> 192000 | N24: =F24-O24 -> -40000 | O24: =SUM(P24:AI24) -> 240000 | T24: 240000 | AJ24: =SUM(X24:AI24) -> 0
B25: 46114 | C25: BS0053 | D25: =IFERROR(VLOOKUP(C25,제품목록,3,FALSE),"") -> 알루미늄리드지 (국내/중국 1-Day Soft)_무광 코팅 | F25: 1500000 | G25: 46125 | H25: 4/14 | K25: 완료 | M25: =IFERROR(_xlfn.XLOOKUP(C25,[1]III.재고현황!O:O,[1]III.재고현황!R:R),) -> 3829000 | N25: =F25-O25 -> 438000 | O25: =SUM(P25:AI25) -> 1062000 | W25: 1062000 | X25: 0 | AJ25: =SUM(X25:AI25) -> 0
B26: 46120 | C26: BS0095 | D26: =IFERROR(VLOOKUP(C26,제품목록,3,FALSE),"") -> 알루미늄리드지 (러시아 Optic Center 1-Day GO 리드지) | E26: HW0315 (5/2 출고) | F26: 1000000 | G26: 46127 | H26: 4/29 | K26: 완료 | M26: =IFERROR(_xlfn.XLOOKUP(C26,[1]III.재고현황!O:O,[1]III.재고현황!R:R),) -> 528000 | N26: =F26-O26 -> -23000 | O26: =SUM(P26:AI26) -> 1023000 | X26: 0 | AH26: 483000 | AI26: 540000 | AJ26: =SUM(X26:AI26) -> 1023000
B27: 46120 | C27: BS0336 | D27: =IFERROR(VLOOKUP(C27,제품목록,3,FALSE),"") -> 알루미늄리드지 (폴란드 FML Oviso Hioxi D 리드지) | E27: X2366 (4/25 출고) | F27: 500000 | G27: 46127 | H27: 4/15 | K27: 완료 | M27: =IFERROR(_xlfn.XLOOKUP(C27,[1]III.재고현황!O:O,[1]III.재고현황!R:R),) -> 0 | N27: =F27-O27 -> -34000 | O27: =SUM(P27:AI27) -> 534000 | X27: 196000 | Y27: 338000 | AJ27: =SUM(X27:AI27) -> 534000
B28: 46120 | C28: BS0344 | D28: =IFERROR(VLOOKUP(C28,제품목록,3,FALSE),"") -> 알루미늄리드지 (이탈리아 Esoform Bioxi D_Visiosan)_유광코팅 | E28: X2376~78 | F28: 1500000 | G28: 46127 | H28: 5/18 | I28: 5/20 | K28: 완료 | M28: =IFERROR(_xlfn.XLOOKUP(C28,[1]III.재고현황!O:O,[1]III.재고현황!R:R),) -> 0 | N28: =F28-O28 -> -72000 | O28: =SUM(P28:AI28) -> 1572000 | X28: 744000 | Y28: 828000 | AJ28: =SUM(X28:AI28) -> 1572000
B29: 46120 | C29: BS0007 | D29: =IFERROR(VLOOKUP(C29,제품목록,3,FALSE),"") -> 알루미늄리드지 (원데이-데일리)_유광 코팅 | E29: HW0312 (5/2 출고) | F29: 1000000 | G29: 46129 | H29: 4/16 | K29: 완료 | M29: =IFERROR(_xlfn.XLOOKUP(C29,[1]III.재고현황!O:O,[1]III.재고현황!R:R),) -> 0 | N29: =F29-O29 -> -43000 | O29: =SUM(P29:AI29) -> 1043000 | Y29: 497000 | Z29: 546000 | AJ29: =SUM(X29:AI29) -> 1043000
B30: 46120 | C30: BS0103 | D30: =IFERROR(VLOOKUP(C30,제품목록,3,FALSE),"") -> 알루미늄리드지 (이태리 soleko US 58% 1day)_유광 코팅 | E30: V3066~V3070 (5/15 출고) | F30: 500000 | G30: 46129 | K30: 완료 | M30: =IFERROR(_xlfn.XLOOKUP(C30,[1]III.재고현황!O:O,[1]III.재고현황!R:R),) -> 0 | N30: =F30-O30 -> -377000 | O30: =SUM(P30:AI30) -> 877000 | Z30: 877000 | AJ30: =SUM(X30:AI30) -> 877000
B31: 46127 | C31: BS0103 | D31: =IFERROR(VLOOKUP(C31,제품목록,3,FALSE),"") -> 알루미늄리드지 (이태리 soleko US 58% 1day)_유광 코팅 | E31: V3066~V3070 (5/15 출고) | F31: 300000 | G31: 46132 | K31: 완료 | M31: =IFERROR(_xlfn.XLOOKUP(C31,[1]III.재고현황!O:O,[1]III.재고현황!R:R),) -> 0 | N31: =F31-O31 -> 300000 | O31: =SUM(P31:AI31) -> 0 | AJ31: =SUM(X31:AI31) -> 0
B32: 46120 | C32: BS0261 | D32: =IFERROR(VLOOKUP(C32,제품목록,3,FALSE),"") -> 알루미늄리드지 (PIA_1D 55% Resay 리드지) | F32: 1500000 | G32: 46132 | H32: 5/7~ | K32: 완료 | M32: =IFERROR(_xlfn.XLOOKUP(C32,[1]III.재고현황!O:O,[1]III.재고현황!R:R),) -> 459000 | N32: =F32-O32 -> 189000 | O32: =SUM(P32:AI32) -> 1311000 | Q32: 555000 | R32: 756000 | AJ32: =SUM(X32:AI32) -> 0
B33: 46120 | C33: BS0036 | D33: =IFERROR(VLOOKUP(C33,제품목록,3,FALSE),"") -> 알루미늄리드지 (PIA 1Day)_유광 코팅 | F33: 2000000 | G33: 46132 | K33: 완료 | M33: =IFERROR(_xlfn.XLOOKUP(C33,[1]III.재고현황!O:O,[1]III.재고현황!R:R),) -> 1115000 | N33: =F33-O33 -> -150000 | O33: =SUM(P33:AI33) -> 2150000 | Y33: 2150000 | AJ33: =SUM(X33:AI33) -> 2150000
B34: 46127 | C34: BS0243 | D34: =IFERROR(VLOOKUP(C34,제품목록,3,FALSE),"") -> 알루미늄리드지 (영국 FGC SiHy 1Day 리드지) | E34: X2395 (5/11 출고) | F34: 300000 | G34: 46139 | H34: 4/27 | K34: 완료 | N34: =F34-O34 -> -36000 | O34: =SUM(P34:AI34) -> 336000 | AF34: 336000 | AJ34: =SUM(X34:AI34) -> 336000
B35: 46127 | C35: BS0284 | D35: =IFERROR(VLOOKUP(C35,제품목록,3,FALSE),"") -> 알루미늄리드지 (중국 Lensmart_Clalen_55% Metha 1Day_30P) | E35: 5/25 출고 | F35: 400000 | G35: 46142 | H35: 5/11 | K35: 완료 | N35: =F35-O35 -> -48000 | O35: =SUM(P35:AI35) -> 448000 | S35: 448000 | AJ35: =SUM(X35:AI35) -> 0
B36: 46127 | C36: BS0031 | D36: =IFERROR(VLOOKUP(C36,제품목록,3,FALSE),"") -> 알루미늄리드지 (원데이-MPG&E)_유광 코팅 | E36: 5/18 출고 | F36: 300000 | G36: 46143 | H36: 5/14 | K36: 완료 | N36: =F36-O36 -> -49000 | O36: =SUM(P36:AI36) -> 349000 | T36: 349000 | AJ36: =SUM(X36:AI36) -> 0
B37: 46127 | C37: BS0263 | D37: =IFERROR(VLOOKUP(C37,제품목록,3,FALSE),"") -> 알루미늄리드지 (영국 FGC SiHy 1Day MF 리드지) | E37: X2396 (5/11 출고) | F37: 300000 | G37: 46139 | H37: 4/23 | K37: 완료 | N37: =F37-O37 -> -31000 | O37: =SUM(P37:AI37) -> 331000 | AE37: 331000 | AJ37: =SUM(X37:AI37) -> 331000
B38: 46128 | C38: BS0334 | D38: 알루미늄리드지 (Clalen O2O2 Color 1Month Micelia)_무광 | E38: 202604010001(국내) | F38: 150000 | G38: 46135 | H38: 4/23 | K38: 완료 | N38: =F38-O38 -> -58000 | O38: =SUM(P38:AI38) -> 208000 | AB38: 208000 | AJ38: =SUM(X38:AI38) -> 208000
B39: 46132 | C39: BS0059 | D39: 알루미늄리드지 (Bella 1Day Color)_유광 코팅 | F39: 500000 | G39: 46139 | H39: 4/28 | K39: 완료 | N39: =F39-O39 -> -27000 | O39: =SUM(P39:AI39) -> 527000 | AG39: 527000 | AJ39: =SUM(X39:AI39) -> 527000
B40: 46132 | C40: BS0227 | D40: =IFERROR(VLOOKUP(C40,제품목록,3,FALSE),"") -> 알루미늄리드지(윙크컴퍼니 Winc Clear Air Plus 1Day)_유광 코팅 | F40: 300000 | G40: 46142 | H40: 5/8 | K40: 완료 | N40: =F40-O40 -> -57000 | O40: =SUM(P40:AI40) -> 357000 | R40: 357000 | AJ40: =SUM(X40:AI40) -> 0
B41: 46132 | C41: BS0154 | D41: =IFERROR(VLOOKUP(C41,제품목록,3,FALSE),"") -> 알루미늄리드지 (공용 Alcon Freshlook)_유광 코팅 | F41: 300000 | G41: 46146 | H41: 5/13 | K41: 완료 | N41: =F41-O41 -> -46000 | O41: =SUM(P41:AI41) -> 346000 | U41: 346000 | AJ41: =SUM(X41:AI41) -> 0
...

Sheet II.리드지재고관리
B2: II. 리드지용 재고관리
B3: 일자 | C3: 원자재(입고예정) | E3: 원자재(희성보관) | G3: 에이징완료 (희성보관) | H3: 인쇄대기 (CMS보관)
B4: 안전재고 설정기준 | C4: MIN 1개월분 | E4: MIN 1개월분 | G4: MIN 1000만개 | H4: MIN 500만개
B5: 46163 | C5: CPP | D5: 40000000 | E5: CPP | F5: 24000000 | G5: 12000000 | H5: 5300000
C6: AL | D6: 111800000 | E6: AL | F6: 26000000
C7: PET | D7: 131000000 | E7: PET | F7: 60000000
B8: 46170 | C8: CPP | E8: CPP
C9: AL | E9: AL
C10: PET | E10: PET
B11: 46177 | C11: CPP | E11: CPP
C12: AL | E12: AL
C13: PET | E13: PET
B14: 46187 | C14: CPP | E14: CPP
C15: AL | E15: AL
C16: PET | E16: PET
B17: 46191 | C17: CPP | E17: CPP
C18: AL | E18: AL
C19: PET | E19: PET
B20: 46198 | C20: CPP | E20: CPP
C21: AL | E21: AL
C22: PET | E22: PET
B23: ※ 입고 예정분은 공급사 창고 보관분 포함

Sheet RD.참조DATA
F1: 2026-04-09기준
A2: 품목코드 | B2: 규격 | C2: 품목명 | D2: 품목구분 | E2: 대분류코드 | F2: 중분류코드
A3: BS0001 | B3: SJ-170 | C3: 블리스터케이스(소사각-SJ) | D3: 부자재 | E3: 부자재 | F3: 소프트렌즈(B)
A4: BS0002 | B4: SJ-170 | C4: 블리스터케이스(중사각-SJ) | D4: 부자재 | E4: 부자재 | F4: 소프트렌즈(B)
A5: BS0003 | B5: SJ-170 | C5: 블리스터케이스(원형-SJ) | D5: 부자재 | E5: 부자재 | F5: 소프트렌즈(B)
A6: BS0004 | B6: SJ-170 BS0004-001 | C6: 블리스터케이스(원데이_SJ) | D6: 부자재 | E6: 부자재 | F6: 소프트렌즈(B)
A7: BS0005 | B7: BS0005-002 | C7: 알루미늄리드지 (Monthly_무지) | D7: 부자재 | E7: 부자재 | F7: 소프트렌즈(B)
A8: BS0006 | B8: BS0006-001 | C8: 알루미늄리드지 (1-Day Soft)구형_무광 코팅 | D8: 부자재 | E8: 부자재 | F8: 소프트렌즈(B)
A9: BS0007 | B9: BS0007-001 | C9: 알루미늄리드지 (원데이-데일리)_유광 코팅 | D9: 부자재 | E9: 부자재 | F9: 소프트렌즈(B)
A10: BS0008 | B10: IRIS JAZZ BLACK | C10: 원데이써클리드지(IRIS_JB) | D10: 부자재 | E10: 부자재 | F10: 소프트렌즈(B)
A11: BS0009 | B11: IRIS SOUL BROWN | C11: 원데이써클리드지(IRIS_SB) | D11: 부자재 | E11: 부자재 | F11: 소프트렌즈(B)
A12: BS0010 | B12: BS0010-001 | C12: 알루미늄리드지(원데이_아이리스)구형 | D12: 부자재 | E12: 부자재 | F12: 소프트렌즈(B)
A13: BS0011 | B13: BS0011-001 | C13: 알루미늄리드지 (원데이-스플레쉬)_유광 코팅 | D13: 부자재 | E13: 부자재 | F13: 소프트렌즈(B)
... A36: BS0034 | B36: BS0034-001 | C36: 알루미늄리드지 (원데이-스플레쉬) 구 디자인_유광 코팅 | D36: 부자재 | E36: 부자재 | F36: 소프트렌즈(B)
A37: BS0035 | C37: 중국 Hydron tray | D37: 부자재 | E37: 부자재 | F37: 소프트렌즈(B)
A38: BS0036 | B38: BS0036-001 | C38: 알루미늄리드지 (PIA 1Day)_유광 코팅 | D38: 부자재 | E38: 부자재 | F38: 소프트렌즈(B)
A39: BS0037 | B39: BS0037-001 | C39: 알루미늄리드지 (아이리스 2weeks)_유광 코팅 | D39: 부자재 | E39: 부자재 | F39: 소프트렌즈(B)
A40: BS0038 | B40: BS0038-003 | C40: 알루미늄리드지 (Clalen 55S)_유광 코팅 | D40: 부자재 | E40: 부자재 | F40: 소프트렌즈(B)
A41: BS0039 | B41: BS0039-002 | C41: 알루미늄리드지 (신시아 2week UV)_유광 코팅 | D41: 부자재 | E41: 부자재 | F41: 소프트렌즈(B)
A42: BS0040 | B42: BS0040-001 | C42: 알루미늄리드지(아시아네트웍스-FlowerEyes) | D42: 부자재 | E42: 부자재 | F42: 소프트렌즈(B)
A43: BS0041 | B43: BS0041-001 | C43: 알루미늄리드지(아시아네트웍스-돈키PB) | D43: 부자재 | E43: 부자재 | F43: 소프트렌즈(B)
A44: BS0042 | B44: SJ-170 | C44: 블리스터케이스(신시아_SJ) | D44: 부자재 | E44: 부자재 | F44: 소프트렌즈(B)
A45: BS0043 | B45: BS0043-001 | C45: 알루미늄리드지(Asia-리치베이비) | D45: 부자재 | E45: 부자재 | F45: 소프트렌즈(B)
A46: BS0044 | B46: BS0044-001 | C46: 알루미늄리드지(Asia-EyeGrace) | D46: 부자재 | E46: 부자재 | F46: 소프트렌즈(B)
A47: BS0045 | B47: BS0045-001 | C47: 알루미늄리드지(Asia-주얼리하트) | D47: 부자재 | E47: 부자재 | F47: 소프트렌즈(B)
A48: BS0046 | B48: BS0046-001 | C48: 알루미늄리드지 (무지-백색w210) | D48: 부자재 | E48: 부자재 | F48: 소프트렌즈(B)
A49: BS0047 | B49: SJ-170 | C49: 블리스터케이스(중사각-샌딩_SJ) | D49: 부자재 | E49: 부자재 | F49: 소프트렌즈(B)
... A301: BS0300 | B301: BS0300-001 | C301: 알루미늄리드지 (이탈리아 Esoform SiHy 1Day 리드지) | D301: 부자재 | E301: 부자재 | F301: 소프트렌즈(B)
A302: BS0301 | B302: 5구 파레트(원형)_PP-TD20%(베이지) | C302: 타공소독케이스 (신형) | D302: 소모품 | E302: 소모품
A303: BS0302 | B303: SJ-170(융착산 형상 6개 추가) | C303: 블리스터케이스(원데이_SJ) | D303: 부자재 | E303: 부자재 | F303: 소프트렌즈(B)
A304: BS0303 | B304: BS0303-001 | C304: 알루미늄리드지 ((주)코코엘 Lighly Creamy 1Day) | D304: 부자재 | E304: 부자재 | F304: 소프트렌즈(B)
A305: BS0304 | B305: BS0304-001 | C305: 알루미늄리드지(Lighly Creamy 1Day Choco_30P) | D305: 부자재 | E305: 부자재 | F305: 소프트렌즈(B)
A306: BS0305 | B306: BS0305-001 | C306: 알루미늄리드지(Lighly Creamy 1Day Brown_30P) | D306: 부자재 | E306: 부자재 | F306: 소프트렌즈(B)
A307: BS0306 | B307: BS0306-001 | C307: 알루미늄리드지(Lighly Creamy 1Day Gray_30P) | D307: 부자재 | E307: 부자재 | F307: 소프트렌즈(B)
A308: BS0307 | B308: BS0307-001 | C308: 알루미늄리드지(Lighly Creamy 1Day Rose_30P) | D308: 부자재 | E308: 부자재 | F308: 소프트렌즈(B)
A309: BS0308 | B309: BS0308-001 | C309: 알루미늄리드지(Lighly Creamy 1Day Black_30P) | D309: 부자재 | E309: 부자재 | F309: 소프트렌즈(B)
A310: BS0309 | B310: BS0309-001 | C310: 알루미늄리드지 (러시아 Optic Center Adria X) | D310: 부자재 | E310: 부자재 | F310: 소프트렌즈(B)
A311: BS0310 | B311: BS0310-001 | C311: 알루미늄리드지 (태국 MG Medical Group_SISSE ONE DAY_BaBe Apricot 리드지) | D311: 부자재 | E311: 부자재 | F311: 소프트렌즈(B)
A312: BS0311 | B312: BS0311-001 | C312: 알루미늄리드지 (태국 MG Medical Group_SISSE ONE DAY_PoPo Milk Tea 리드지) | D312: 부자재 | E312: 부자재 | F312: 소프트렌즈(B)
A313: BS0312 | B313: BS0312-001 | C313: 알루미늄리드지 (태국 MG Medical Group_SISSE ONE DAY_PoPo Ceylon 리드지) | D313: 부자재 | E313: 부자재 | F313: 소프트렌즈(B)
...

Sheet RD.재고현황
A1: 창고 | B1: 구분 | C1: 품목코드 | D1: 품목명 | E1: 규격 | F1: 대분류 | G1: 중분류 | H1: Lot.No | I1: 기초 | J1: 입고 | K1: 출고 | L1: 재고 | M1: 검사대기 | N1: 단위 | O1: 합계 : 재고 | P1: 열 레이블
A2: 용마창고 | B2: 부자재 | C2: BS0053 | D2: 알루미늄리드지 (국내/중국 1-Day Soft)_무광 코팅 | E2: BS0053-002 | F2: 부자재 | G2: 소프트렌즈(B) | I2: 0 | J2: 0 | K2: 0 | L2: 0 | M2: 0 | N2: EA | O2: 행 레이블 | P2: A관 공정부자재 | Q2: C관 공정부자재 | R2: L관창고(자재) | S2: 총합계
A3: 용마창고 | B3: 부자재 | C3: BS0073 | D3: 알루미늄리드지 (일본 PIA 1day 55%)_유광 코팅 | E3: BS0073-002 | F3: 부자재 | G3: 소프트렌즈(B) | I3: 0 | J3: 0 | K3: 0 | L3: 0 | M3: 0 | N3: EA | O3: BS0005 | P3: 677965 | Q3: 0 | R3: 1200030 | S3: 1877995
A4: 용마창고 | B4: 부자재 | C4: BS0129 | D4: 알루미늄리드지 (중국향 Clalen RINA 1-Day 리드지)_유광 코팅 | E4: BS0129-001 | F4: 부자재 | G4: 소프트렌즈(B) | I4: 0 | J4: 0 | K4: 0 | L4: 0 | M4: 0 | N4: EA | O4: BS0006 | Q4: 89788 | R4: 100000 | S4: 189788
A5: 용마창고 | B5: 부자재 | C5: BS0155 | D5: 알루미늄리드지 (공용 Alcon Freshlook CC Lens)_유광 코팅 | E5: BS0155-001 | F5: 부자재 | G5: 소프트렌즈(B) | I5: 0 | J5: 0 | K5: 0 | L5: 0 | M5: 0 | N5: EA | O5: BS0007 | Q5: 10366 | R5: 0 | S5: 10366
A6: 용마창고 | B6: 부자재 | C6: BS0214 | D6: 알루미늄리드지 (Bella 리뉴얼 원데이 리드지(아랍))_유광코팅 | E6: BS0214-001 | F6: 부자재 | G6: 소프트렌즈(B) | I6: 0 | J6: 0 | K6: 0 | L6: 0 | M6: 0 | N6: EA | O6: BS0010 | R6: 0 | S6: 0
A7: L관창고(자재) | B7: 부자재 | C7: BS0005 | D7: 알루미늄리드지 (Monthly_무지) | E7: BS0005-002 | F7: 부자재 | G7: 소프트렌즈(B) | I7: 1560039 | J7: 0 | K7: 360009 | L7: 1200030 | M7: 0 | N7: EA | O7: BS0011 | Q7: 77298 | R7: 98000 | S7: 175298
A8: L관창고(자재) | B8: 부자재 | C8: BS0006 | D8: 알루미늄리드지 (1-Day Soft)구형_무광 코팅 | E8: BS0006-001 | F8: 부자재 | G8: 소프트렌즈(B) | I8: 100000 | J8: 0 | K8: 0 | L8: 100000 | M8: 0 | N8: EA | O8: BS0012 | R8: 0 | S8: 0
A9: L관창고(자재) | B9: 부자재 | C9: BS0007 | D9: 알루미늄리드지 (원데이-데일리)_유광 코팅 | E9: BS0007-001 | F9: 부자재 | G9: 소프트렌즈(B) | I9: 148000 | J9: 0 | K9: 148000 | L9: 0 | M9: 0 | N9: EA | O9: BS0013 | R9: 0 | S9: 0
A10: L관창고(자재) | B10: 부자재 | C10: BS0010 | D10: 알루미늄리드지(원데이_아이리스)구형 | E10: BS0010-001 | F10: 부자재 | G10: 소프트렌즈(B) | I10: 0 | J10: 0 | K10: 0 | L10: 0 | M10: 0 | N10: EA | O10: BS0014 | R10: 0 | S10: 0
A11: L관창고(자재) | B11: 부자재 | C11: BS0011 | D11: 알루미늄리드지 (원데이-스플레쉬)_유광 코팅 | E11: BS0011-001 | F11: 부자재 | G11: 소프트렌즈(B) | I11: 98000 | J11: 0 | K11: 0 | L11: 98000 | M11: 0 | N11: EA | O11: BS0023 | R11: 0 | S11: 0
A12: L관창고(자재) | B12: 부자재 | C12: BS0012 | D12: 알루미늄리드지(LuxeBrown) | E12: BS0012-001 | F12: 부자재 | G12: 소프트렌즈(B) | I12: 0 | J12: 0 | K12: 0 | L12: 0 | M12: 0 | N12: EA | O12: BS0031 | Q12: 132465 | R12: 48000 | S12: 180465
A13: L관창고(자재) | B13: 부자재 | C13: BS0013 | D13: 알루미늄리드지(SheerBlack) | E13: BS0013-001 | F13: 부자재 | G13: 소프트렌즈(B) | I13: 0 | J13: 0 | K13: 0 | L13: 0 | M13: 0 | N13: EA | O13: BS0032 | R13: 0 | S13: 0
A14: L관창고(자재) | B14: 부자재 | C14: BS0014 | D14: 알루미늄리드지(Sheerbrown) | E14: BS0014-001 | F14: 부자재 | G14: 소프트렌즈(B) | I14: 0 | J14: 0 | K14: 0 | L14: 0 | M14: 0 | N14: EA | O14: BS0033 | R14: 0 | S14: 0
A15: L관창고(자재) | B15: 부자재 | C15: BS0023 | D15: 알루미늄리드지(1-Day Facil) | E15: BS0023-001 | F15: 부자재 | G15: 소프트렌즈(B) | I15: 0 | J15: 0 | K15: 0 | L15: 0 | M15: 0 | N15: EA | O15: BS0034 | R15: 0 | S15: 0
A16: L관창고(자재) | B16: 부자재 | C16: BS0031 | D16: 알루미늄리드지 (원데이-MPG&E)_유광 코팅 | E16: BS0031-004 | F16: 부자재 | G16: 소프트렌즈(B) | I16: 48000 | J16: 0 | K16: 0 | L16: 48000 | M16: 0 | N16: EA | O16: BS0036 | Q16: 105185 | R16: 1115000 | S16: 1220185
A17: L관창고(자재) | B17: 부자재 | C17: BS0032 | D17: 알루미늄리드지 (무지-백색) | E17: BS0032-001 | F17: 부자재 | G17: 소프트렌즈(B) | I17: 0 | J17: 0 | K17: 0 | L17: 0 | M17: 0 | N17: EA | O17: BS0037 | R17: 0 | S17: 0
A18: L관창고(자재) | B18: 부자재 | C18: BS0033 | D18: 알루미늄리드지(1-Day LARME) | E18: BS0033-001 | F18: 부자재 | G18: 소프트렌즈(B) | I18: 0 | J18: 0 | K18: 0 | L18: 0 | M18: 0 | N18: EA | O18: BS0038 | Q18: 19794 | R18: 62553 | S18: 82347
A19: L관창고(자재) | B19: 부자재 | C19: BS0034 | D19: 알루미늄리드지 (원데이-스플레쉬) 구 디자인_유광 코팅 | E19: BS0034-001 | F19: 부자재 | G19: 소프트렌즈(B) | I19: 0 | J19: 0 | K19: 0 | L19: 0 | M19: 0 | N19: EA | O19: BS0039 | Q19: 10227 | R19: 259200 | S19: 269427
A20: L관창고(자재) | B20: 부자재 | C20: BS0036 | D20: 알루미늄리드지 (PIA 1Day)_유광 코팅 | E20: BS0036-001 | F20: 부자재 | G20: 소프트렌즈(B) | I20: 2525000 | J20: 0 | K20: 1410000 | L20: 1115000 | M20: 0 | N20: EA | O20: BS0040 | R20: 0 | S20: 0
A21: L관창고(자재) | B21: 부자재 | C21: BS0037 | D21: 알루미늄리드지 (아이리스 2weeks)_유광 코팅 | E21: BS0037-001 | F21: 부자재 | G21: 소프트렌즈(B) | I21: 0 | J21: 0 | K21: 0 | L21: 0 | M21: 0 | N21: EA | O21: BS0041 | R21: 0 | S21: 0
A22: L관창고(자재) | B22: 부자재 | C22: BS0038 | D22: 알루미늄리드지 (Clalen 55S)_유광 코팅 | E22: BS0038-003 | F22: 부자재 | G22: 소프트렌즈(B) | I22: 62553 | J22: 0 | K22: 0 | L22: 62553 | M22: 0 | N22: EA | O22: BS0043 | R22: 0 | S22: 0
A23: L관창고(자재) | B23: 부자재 | C23: BS0039 | D23: 알루미늄리드지 (신시아 2week UV)_유광 코팅 | E23: BS0039-002 | F23: 부자재 | G23: 소프트렌즈(B) | I23: 259200 | J23: 0 | K23: 0 | L23: 259200 | M23: 0 | N23: EA | O23: BS0044 | R23: 0 | S23: 0
A24: L관창고(자재) | B24: 부자재 | C24: BS0040 | D24: 알루미늄리드지(아시아네트웍스-FlowerEyes) | E24: BS0040-001 | F24: 부자재 | G24: 소프트렌즈(B) | I24: 0 | J24: 0 | K24: 0 | L24: 0 | M24: 0 | N24: EA | O24: BS0045 | R24: 0 | S24: 0
A25: L관창고(자재) | B25: 부자재 | C25: BS0041 | D25: 알루미늄리드지(아시아네트웍스-돈키PB) | E25: BS0041-001 | F25: 부자재 | G25: 소프트렌즈(B) | I25: 0 | J25: 0 | K25: 0 | L25: 0 | M25: 0 | N25: EA | O25: BS0046 | R25: 0 | S25: 0
A26: L관창고(자재) | B26: 부자재 | C26: BS0043 | D26: 알루미늄리드지(Asia-리치베이비) | E26: BS0043-001 | F26: 부자재 | G26: 소프트렌즈(B) | I26: 0 | J26: 0 | K26: 0 | L26: 0 | M26: 0 | N26: EA | O26: BS0048 | Q26: 201670 | R26: 96000 | S26: 297670
A27: L관창고(자재) | B27: 부자재 | C27: BS0044 | D27: 알루미늄리드지(Asia-EyeGrace) | E27: BS0044-001 | F27: 부자재 | G27: 소프트렌즈(B) | I27: 0 | J27: 0 | K27: 0 | L27: 0 | M27: 0 | N27: EA | O27: BS0049 | R27: 46000 | S27: 46000
A28: L관창고(자재) | B28: 부자재 | C28: BS0045 | D28: 알루미늄리드지(Asia-주얼리하트) | E28: BS0045-001 | F28: 부자재 | G28: 소프트렌즈(B) | I28: 0 | J28: 0 | K28: 0 | L28: 0 | M28: 0 | N28: EA | O28: BS0050 | Q28: 444262 | R28: 775000 | S28: 1219262
A29: L관창고(자재) | B29: 부자재 | C29: BS0046 | D29: 알루미늄리드지 (무지-백색w210) | E29: BS0046-001 | F29: 부자재 | G29: 소프트렌즈(B) | I29: 0 | J29: 0 | K29: 0 | L29: 0 | M29: 0 | N29: EA | O29: BS0051 | R29: 0 | S29: 0
A30: L관창고(자재) | B30: 부자재 | C30: BS0048 | D30: 알루미늄리드지 (Metha Daily)_유광 코팅 | E30: BS0048-001 | F30: 부자재 | G30: 소프트렌즈(B) | I30: 390000 | J30: 0 | K30: 294000 | L30: 96000 | M30: 0 | N30: EA | O30: BS0052 | Q30: 72375 | R30: 480000 | S30: 552375
A31: L관창고(자재) | B31: 부자재 | C31: BS0049 | D31: 알루미늄리드지 (신시아_원데이UV모이스쳐)_무광 코팅 | E31: BS0049-002 | F31: 부자재 | G31: 소프트렌즈(B) | I31: 46000 | J31: 0 | K31: 0 | L31: 46000 | M31: 0 | N31: EA | O31: BS0053 | Q31: 179719 | R31: 3829000 | S31: 4008719
A32: L관창고(자재) | B32: 부자재 | C32: BS0050 | D32: 알루미늄리드지 (Iris_수지그레이)_무광 코팅 | E32: BS0050-002 | F32: 부자재 | G32: 소프트렌즈(B) | I32: 1458000 | J32: 0 | K32: 683000 | L32: 775000 | M32: 0 | N32: EA | O32: BS0054 | Q32: 969746 | R32: 0 | S32: 969746
A33: L관창고(자재) | B33: 부자재 | C33: BS0051 | D33: 알루미늄리드지 (스타비전_넬리브라운)_유광 코팅 | E33: BS0051-002 | F33: 부자재 | G33: 소프트렌즈(B) | I33: 0 | J33: 0 | K33: 0 | L33: 0 | M33: 0 | N33: EA | O33: BS0055 | R33: 0 | S33: 0
A34: L관창고(자재) | B34: 부자재 | C34: BS0052 | D34: 알루미늄리드지 (Iris-Toric)_무광 코팅 | E34: BS0052-002 | F34: 부자재 | G34: 소프트렌즈(B) | I34: 675000 | J34: 0 | K34: 195000 | L34: 480000 | M34: 0 | N34: EA | O34: BS0057 | Q34: 121744 | R34: 539000 | S34: 660744
A35: L관창고(자재) | B35: 부자재 | C35: BS0053 | D35: 알루미늄리드지 (국내/중국 1-Day Soft)_무광 코팅 | E35: BS0053-002 | F35: 부자재 | G35: 소프트렌즈(B) | I35: 722000 | J35: 3107000 | K35: 0 | L35: 3829000 | M35: 0 | N35: EA | O35: BS0058 | R35: 0 | S35: 0
A36: L관창고(자재) | B36: 부자재 | C36: BS0054 | D36: 알루미늄리드지 (국내/중국 원데이_아이리스)_무광 코팅 | E36: BS0054-003 | F36: 부자재 | G36: 소프트렌즈(B) | I36: 3402000 | J36: 864000 | K36: 4266000 | L36: 0 | M36: 0 | N36: EA | O36: BS0059 | Q36: 16586 | R36: 389000 | S36: 405586
A37: L관창고(자재) | B37: 부자재 | C37: BS0055 | D37: 알루미늄리드지 (스타비전_아이스그레이)_유광 코팅 | E37: BS0055-002 | F37: 부자재 | G37: 소프트렌즈(B) | I37: 0 | J37: 0 | K37: 0 | L37: 0 | M37: 0 | N37: EA | O37: BS0060 | R37: 0 | S37: 0
A38: L관창고(자재) | B38: 부자재 | C38: BS0057 | D38: 알루미늄리드지 (Iris-알리샤브라운)_무광 코팅 | E38: BS0057-002 | F38: 부자재 | G38: 소프트렌즈(B) | I38: 48000 | J38: 587000 | K38: 96000 | L38: 539000 | M38: 0 | N38: EA | O38: BS0061 | R38: 0 | S38: 0
A39: L관창고(자재) | B39: 부자재 | C39: BS0058 | D39: 알루미늄리드지 (프랑스 Ophtalmic 1-day 블랙)_무광 코팅 | E39: BS0058-001 | F39: 부자재 | G39: 소프트렌즈(B) | I39: 0 | J39: 0 | K39: 0 | L39: 0 | M39: 0 | N39: EA | O39: BS0062 | Q39: 0 | R39: 95000 | S39: 95000
A40: L관창고(자재) | B40: 부자재 | C40: BS0059 | D40: 알루미늄리드지 (Bella_1Day_컬러 리드지)_유광 코팅 | E40: BS0059-001 | F40: 부자재 | G40: 소프트렌즈(B) | I40: 389000 | J40: 0 | K40: 0 | L40: 389000 | M40: 0 | N40: EA | O40: BS0063 | R40: 0 | S40: 0
...
